[
    "When a second user signs in, they get this error:\n\nEnvironment:\n\n\nRequest Method: GET\nRequest URL: http://127.0.0.1:8000/accounts/google/login/callback/?state=IWk6ABfpJ4ygsZAZ&code=4%2F0AVGzR1AxKLe4-WMLpXiZyhJEMOCYuKZRRXrPoXOk0ZCyg4M2ZSxVJnxApVtP5fbBPbkQFQ&scope=email+profile+https%3A%2F%2Fwww.googleapis.com%2Fauth%2Fuserinfo.profile+https%3A%2F%2Fwww.googleapis.com%2Fauth%2Fuserinfo.email+openid&authuser=1&prompt=consent\n\nDjango Version: 5.2.7\nPython Version: 3.13.6\nInstalled Applications:\n['django.contrib.admin',\n 'django.contrib.auth',\n 'django.contrib.contenttypes',\n 'django.contrib.sessions',\n 'django.contrib.messages',\n 'django.contrib.staticfiles',\n 'django.contrib.sites',\n 'allauth',\n 'allauth.account',\n 'allauth.socialaccount',\n 'allauth.socialaccount.providers.google',\n 'django_app']\nInstalled Middleware:\n['django.middleware.security.SecurityMiddleware',\n 'django.contrib.sessions.middleware.SessionMiddleware',\n 'django.middleware.common.CommonMiddleware',\n 'django.middleware.csrf.CsrfViewMiddleware',\n 'django.contrib.auth.middleware.AuthenticationMiddleware',\n 'django.contrib.messages.middleware.MessageMiddleware',\n 'django.middleware.clickjacking.XFrameOptionsMiddleware',\n 'allauth.account.middleware.AccountMiddleware']\n\n\n\nTraceback (most recent call last):\n  File \"/Users/abreslav/codespeak/releases/0.0.1-alpha/uv1-todo-0/.venv/lib/python3.13/site-packages/django/db/backends/utils.py\", line 105, in _execute\n    return self.cursor.execute(sql, params)\n           ^^^^^^^^^^^^^^^^^^^^^^^^^^^^^^^^\n  File \"/Users/abreslav/codespeak/releases/0.0.1-alpha/uv1-todo-0/.venv/lib/python3.13/site-packages/django/db/backends/sqlite3/base.py\", line 360, in execute\n    return super().execute(query, params)\n           ^^^^^^^^^^^^^^^^^^^^^^^^^^^^^^\n\nThe above exception (UNIQUE constraint failed: auth_user.username) was the direct cause of the following exception:\n  File \"/Users/abreslav/codespeak/releases/0.0.1-alpha/uv1-todo-0/.venv/lib/python3.13/site-packages/django/core/handlers/exception.py\", line 55, in inner\n    response = get_response(request)\n               ^^^^^^^^^^^^^^^^^^^^^\n  File \"/Users/abreslav/codespeak/releases/0.0.1-alpha/uv1-todo-0/.venv/lib/python3.13/site-packages/django/core/handlers/base.py\", line 197, in _get_response\n    response = wrapped_callback(request, *callback_args, **callback_kwargs)\n               ^^^^^^^^^^^^^^^^^^^^^^^^^^^^^^^^^^^^^^^^^^^^^^^^^^^^^^^^^^^^\n  File \"/Users/abreslav/codespeak/releases/0.0.1-alpha/uv1-todo-0/.venv/lib/python3.13/site-packages/allauth/socialaccount/providers/oauth2/views.py\", line 102, in view\n    return self.dispatch(request, *args, **kwargs)\n           ^^^^^^^^^^^^^^^^^^^^^^^^^^^^^^^^^^^^^^^\n  File \"/Users/abreslav/codespeak/releases/0.0.1-alpha/uv1-todo-0/.venv/lib/python3.13/site-packages/allauth/socialaccount/providers/oauth2/views.py\", line 151, in dispatch\n    return complete_social_login(request, login)\n           ^^^^^^^^^^^^^^^^^^^^^^^^^^^^^^^^^^^^^\n  File \"/Users/abreslav/codespeak/releases/0.0.1-alpha/uv1-todo-0/.venv/lib/python3.13/site-packages/allauth/socialaccount/helpers.py\", line 67, in complete_social_login\n    return flows.login.complete_login(request, sociallogin)\n           ^^^^^^^^^^^^^^^^^^^^^^^^^^^^^^^^^^^^^^^^^^^^^^^^\n  File \"/Users/abreslav/codespeak/releases/0.0.1-alpha/uv1-todo-0/.venv/lib/python3.13/site-packages/allauth/socialaccount/internal/flows/login.py\", line 53, in complete_login\n    return _authenticate(request, sociallogin)\n           ^^^^^^^^^^^^^^^^^^^^^^^^^^^^^^^^^^^\n  File \"/Users/abreslav/codespeak/releases/0.0.1-alpha/uv1-todo-0/.venv/lib/python3.13/site-packages/allauth/socialaccount/internal/flows/login.py\", line 80, in _authenticate\n    ret = process_signup(request, sociallogin)\n          ^^^^^^^^^^^^^^^^^^^^^^^^^^^^^^^^^^^^\n  File \"/Users/abreslav/codespeak/releases/0.0.1-alpha/uv1-todo-0/.venv/lib/python3.13/site-packages/allauth/socialaccount/internal/flows/signup.py\", line 124, in process_signup\n    get_adapter().save_user(request, sociallogin, form=None)\n    ^^^^^^^^^^^^^^^^^^^^^^^^^^^^^^^^^^^^^^^^^^^^^^^^^^^^^^^^\n  File \"/Users/abreslav/codespeak/releases/0.0.1-alpha/uv1-todo-0/.venv/lib/python3.13/site-packages/allauth/socialaccount/adapter.py\", line 106, in save_user\n    sociallogin.save(request)\n    ^^^^^^^^^^^^^^^^^^^^^^^^^\n  File \"/Users/abreslav/codespeak/releases/0.0.1-alpha/uv1-todo-0/.venv/lib/python3.13/site-packages/allauth/socialaccount/models.py\", line 306, in save\n    user.save()\n    ^^^^^^^^^^^\n  File \"/Users/abreslav/codespeak/releases/0.0.1-alpha/uv1-todo-0/.venv/lib/python3.13/site-packages/django/contrib/auth/base_user.py\", line 65, in save\n    super().save(*args, **kwargs)\n    ^^^^^^^^^^^^^^^^^^^^^^^^^^^^^\n  File \"/Users/abreslav/codespeak/releases/0.0.1-alpha/uv1-todo-0/.venv/lib/python3.13/site-packages/django/db/models/base.py\", line 902, in save\n    self.save_base(\n    ^\n  File \"/Users/abreslav/codespeak/releases/0.0.1-alpha/uv1-todo-0/.venv/lib/python3.13/site-packages/django/db/models/base.py\", line 1008, in save_base\n    updated = self._save_table(\n              \n  File \"/Users/abreslav/codespeak/releases/0.0.1-alpha/uv1-todo-0/.venv/lib/python3.13/site-packages/django/db/models/base.py\", line 1169, in _save_table\n    results = self._do_insert(\n              \n  File \"/Users/abreslav/codespeak/releases/0.0.1-alpha/uv1-todo-0/.venv/lib/python3.13/site-packages/django/db/models/base.py\", line 1210, in _do_insert\n    return manager._insert(\n           \n  File \"/Users/abreslav/codespeak/releases/0.0.1-alpha/uv1-todo-0/.venv/lib/python3.13/site-packages/django/db/models/manager.py\", line 87, in manager_method\n    return getattr(self.get_queryset(), name)(*args, **kwargs)\n           ^^^^^^^^^^^^^^^^^^^^^^^^^^^^^^^^^^^^^^^^^^^^^^^^^^^\n  File \"/Users/abreslav/codespeak/releases/0.0.1-alpha/uv1-todo-0/.venv/lib/python3.13/site-packages/django/db/models/query.py\", line 1868, in _insert\n    return query.get_compiler(using=using).execute_sql(returning_fields)\n           ^^^^^^^^^^^^^^^^^^^^^^^^^^^^^^^^^^^^^^^^^^^^^^^^^^^^^^^^^^^^^\n  File \"/Users/abreslav/codespeak/releases/0.0.1-alpha/uv1-todo-0/.venv/lib/python3.13/site-packages/django/db/models/sql/compiler.py\", line 1882, in execute_sql\n    cursor.execute(sql, params)\n    ^^^^^^^^^^^^^^^^^^^^^^^^^^^\n  File \"/Users/abreslav/codespeak/releases/0.0.1-alpha/uv1-todo-0/.venv/lib/python3.13/site-packages/django/db/backends/utils.py\", line 122, in execute\n    return super().execute(sql, params)\n           ^^^^^^^^^^^^^^^^^^^^^^^^^^^^\n  File \"/Users/abreslav/codespeak/releases/0.0.1-alpha/uv1-todo-0/.venv/lib/python3.13/site-packages/django/db/backends/utils.py\", line 79, in execute\n    return self._execute_with_wrappers(\n           \n  File \"/Users/abreslav/codespeak/releases/0.0.1-alpha/uv1-todo-0/.venv/lib/python3.13/site-packages/django/db/backends/utils.py\", line 92, in _execute_with_wrappers\n    return executor(sql, params, many, context)\n           ^^^^^^^^^^^^^^^^^^^^^^^^^^^^^^^^^^^^\n  File \"/Users/abreslav/codespeak/releases/0.0.1-alpha/uv1-todo-0/.venv/lib/python3.13/site-packages/django/db/backends/utils.py\", line 100, in _execute\n    with self.db.wrap_database_errors:\n         ^^^^^^^^^^^^^^^^^^^^^^^^^^^^\n  File \"/Users/abreslav/codespeak/releases/0.0.1-alpha/uv1-todo-0/.venv/lib/python3.13/site-packages/django/db/utils.py\", line 91, in __exit__\n    raise dj_exc_value.with_traceback(traceback) from exc_value\n    ^^^^^^^^^^^^^^^^^^^^^^^^^^^^^^^^^^^^^^^^^^^^^^^^^^^^^^^^^^^\n  File \"/Users/abreslav/codespeak/releases/0.0.1-alpha/uv1-todo-0/.venv/lib/python3.13/site-packages/django/db/backends/utils.py\", line 105, in _execute\n    return self.cursor.execute(sql, params)\n           ^^^^^^^^^^^^^^^^^^^^^^^^^^^^^^^^\n  File \"/Users/abreslav/codespeak/releases/0.0.1-alpha/uv1-todo-0/.venv/lib/python3.13/site-packages/django/db/backends/sqlite3/base.py\", line 360, in execute\n    return super().execute(query, params)\n           ^^^^^^^^^^^^^^^^^^^^^^^^^^^^^^\n\nException Type: IntegrityError at /accounts/google/login/callback/\nException Value: UNIQUE constraint failed: auth_user.username"
]